2025-04-18 21:51:31,458 INFO    StreamThr :2529350 [internal.py:wandb_internal():89] W&B internal server running at pid: 2529350, started at: 2025-04-18 21:51:31.457390
2025-04-18 21:51:31,461 DEBUG   HandlerThread:2529350 [handler.py:handle_request():146] handle_request: status
2025-04-18 21:51:31,503 INFO    WriterThread:2529350 [datastore.py:open_for_write():87] open: /data/goufandi_space/Projects/GS-MARL/gsmarl/results/MPE/exp2/gsmarl/test/wandb/run-20250418_215131-o7s055py/run-o7s055py.wandb
2025-04-18 21:51:31,503 DEBUG   SenderThread:2529350 [sender.py:send():379] send: header
2025-04-18 21:51:31,525 DEBUG   SenderThread:2529350 [sender.py:send():379] send: run
2025-04-18 21:51:32,155 ERROR   SenderThread:2529350 [internal_api.py:execute():373] 403 response executing GraphQL.
2025-04-18 21:51:32,156 ERROR   SenderThread:2529350 [internal_api.py:execute():374] {"errors":[{"message":"permission denied","path":["upsertBucket"],"extensions":{"code":"PERMISSION_ERROR"}}],"data":{"upsertBucket":null}}
2025-04-18 21:51:32,156 ERROR   SenderThread:2529350 [sender.py:send_run():971] It appears that you do not have permission to access the requested resource. Please reach out to the project owner to grant you access. If you have the correct permissions, verify that there are no issues with your networking setup.(Error 403: Forbidden)
Traceback (most recent call last):
  File "/data/goufandi_space/Software/anaconda3/envs/gs_marl/lib/python3.7/site-packages/wandb/sdk/lib/retry.py", line 131, in __call__
    result = self._call_fn(*args, **kwargs)
  File "/data/goufandi_space/Software/anaconda3/envs/gs_marl/lib/python3.7/site-packages/wandb/sdk/internal/internal_api.py", line 369, in execute
    return self.client.execute(*args, **kwargs)  # type: ignore
  File "/data/goufandi_space/Software/anaconda3/envs/gs_marl/lib/python3.7/site-packages/wandb/vendor/gql-0.2.0/wandb_gql/client.py", line 52, in execute
    result = self._get_result(document, *args, **kwargs)
  File "/data/goufandi_space/Software/anaconda3/envs/gs_marl/lib/python3.7/site-packages/wandb/vendor/gql-0.2.0/wandb_gql/client.py", line 60, in _get_result
    return self.transport.execute(document, *args, **kwargs)
  File "/data/goufandi_space/Software/anaconda3/envs/gs_marl/lib/python3.7/site-packages/wandb/sdk/lib/gql_request.py", line 59, in execute
    request.raise_for_status()
  File "/data/goufandi_space/Software/anaconda3/envs/gs_marl/lib/python3.7/site-packages/requests/models.py", line 1024, in raise_for_status
    raise HTTPError(http_error_msg, response=self)
requests.exceptions.HTTPError: 403 Client Error: Forbidden for url: https://api.wandb.ai/graphql

During handling of the above exception, another exception occurred:

Traceback (most recent call last):
  File "/data/goufandi_space/Software/anaconda3/envs/gs_marl/lib/python3.7/site-packages/wandb/sdk/internal/sender.py", line 969, in send_run
    server_run = self._init_run(run, config_value_dict)
  File "/data/goufandi_space/Software/anaconda3/envs/gs_marl/lib/python3.7/site-packages/wandb/sdk/internal/sender.py", line 1028, in _init_run
    commit=run.git.commit or None,
  File "/data/goufandi_space/Software/anaconda3/envs/gs_marl/lib/python3.7/site-packages/wandb/apis/normalize.py", line 73, in wrapper
    raise err
  File "/data/goufandi_space/Software/anaconda3/envs/gs_marl/lib/python3.7/site-packages/wandb/apis/normalize.py", line 41, in wrapper
    return func(*args, **kwargs)
  File "/data/goufandi_space/Software/anaconda3/envs/gs_marl/lib/python3.7/site-packages/wandb/sdk/internal/internal_api.py", line 2221, in upsert_run
    **kwargs,
  File "/data/goufandi_space/Software/anaconda3/envs/gs_marl/lib/python3.7/site-packages/wandb/sdk/internal/internal_api.py", line 344, in gql
    **kwargs,
  File "/data/goufandi_space/Software/anaconda3/envs/gs_marl/lib/python3.7/site-packages/wandb/sdk/lib/retry.py", line 147, in __call__
    retry_timedelta_triggered = check_retry_fn(e)
  File "/data/goufandi_space/Software/anaconda3/envs/gs_marl/lib/python3.7/site-packages/wandb/util.py", line 968, in check_retry_fn
    return fallback_retry_fn(e)
  File "/data/goufandi_space/Software/anaconda3/envs/gs_marl/lib/python3.7/site-packages/wandb/util.py", line 911, in no_retry_auth
    "It appears that you do not have permission to access the requested resource. "
wandb.errors.CommError: It appears that you do not have permission to access the requested resource. Please reach out to the project owner to grant you access. If you have the correct permissions, verify that there are no issues with your networking setup.(Error 403: Forbidden)
2025-04-18 21:51:32,510 DEBUG   HandlerThread:2529350 [handler.py:handle_request():146] handle_request: shutdown
2025-04-18 21:51:32,510 INFO    HandlerThread:2529350 [handler.py:finish():866] shutting down handler
2025-04-18 21:51:32,525 INFO    WriterThread:2529350 [datastore.py:close():296] close: /data/goufandi_space/Projects/GS-MARL/gsmarl/results/MPE/exp2/gsmarl/test/wandb/run-20250418_215131-o7s055py/run-o7s055py.wandb
2025-04-18 21:51:33,248 INFO    SenderThread:2529350 [sender.py:finish():1546] shutting down sender
